Workbook
Name Descuento: [1]Hoja1!$A$1:$A$2
Name nomSubProceso: [2]!tdSubProceso[SubProceso]

Sheet atributos CONSULTA
A1: ESPECIALIDAD | B1: % CONSULTA NUEVA ESPERADO | C1: % ALTAS ESPERADO | D1: % NSP
A2: Pediatría | B2: >33% | C2: >14% | D2: <12%
A3: Medicina Interna | B3: >40% | C3: >14% | D3: <12%
A4: Neonatología
A5: Enfermedad Respiratoria Pediátrica (Broncopulmonar Infantil)
A6: Enfermedad Respiratoria de Adulto (Broncopulmonar)
A7: Cardiología
A8: Mastología | B8: >20% | C8: z5% | D8: <12%
A9: Endocrinología Pediátrica | B9: >25% | C9: >7% | D9: <12%
A10: Endocrinología Adulto
A11: Gastroenterología Pediátrica
A12: Gastroenterología Adulto | B12: >40% | C12: >10% | D12: <12%
A13: Genética Clínica
A14: Hematología
A15: Medicina del adolescente
A16: Nefrología Pediátrica
A17: Nefrología Adulto
A18: Nutrición clínica
A19: Medicina Materno Infantil
A20: Reumatología
A21: Medicina Paliativa y de Manejo del Dolor
A22: Dermatología | B22: >45% | C22: >18% | D22: <12%
A23: Infectología
A24: Inmunología | B24: >25% | C24: >5% | D24: <12%
A25: Geriatría
A26: Medicina Física y Rehabilitación
A27: Medicina Reproductiva e Infertilidad
A28: Neurología Pediátrica | B28: >33% | C28: >10% | D28: <12%
A29: Neurología Adulto | B29: >33% | C29: >14% | D29: <12%
A30: Oncología Médica
A31: Psiquiatría Pediátrica y de La Adolescencia | B31: >20% | C31: >10% | D31: <12%
A32: Psiquiatría Adulto | B32: >20% | C32: >10% | D32: <12%
A33: Cirugía Pediátrica | B33: >40% | C33: >25% | D33: <12%
A34: Cirugía General | B34: >45% | C34: >18% | D34: <12%
A35: Cirugía Digestiva (Alta) | B35: >45% | C35: >18% | D35: <12%
A36: Cirugía de Cabeza, Cuello y Maxilofacial
A37: Cirugía Plástica y Reparadora
A38: Medicina del Deporte
A39: Coloproctología (Cirugía Digestiva Baja) | B39: >45% | C39: >14% | D39: <12%
A40: Cirugía Tórax
...

Sheet 6,2 NO GES ONCO
A1: N° COMGES | B1: INDICADOR | C1: N° INDICADOR | D1: MES | E1: NUMERADOR | F1: DENOMINADOR | G1: Resultado indicador
D2: 45658 | G2: =E2/F2 -> #DIV/0!
D3: 45689 | G3: =E3/F3 -> #DIV/0!
D4: 45717 | G4: =E4/F4 -> #DIV/0! | I4: 29 | J4: 0
D5: 45748 | G5: =E5/F5 -> #DIV/0! | I5: 0 | J5: 2
D6: 45778 | E6: 45 | F6: 47 | G6: =E6/F6 -> 0.95744681 | I6: 16
D7: 45809 | G7: =E7/F7 -> #DIV/0!
D8: 45839 | G8: =E8/F8 -> #DIV/0! | I8: =SUM(I4:I7) -> 45 | J8: =SUM(J4:J7) -> 2 | K8: =SUM(I8:J8) -> 47
D9: 45870 | G9: =E9/F9 -> #DIV/0!
D10: 45901 | G10: =E10/F10 -> #DIV/0!
D11: 45931 | G11: =E11/F11 -> #DIV/0!
D12: 45962 | G12: =E12/F12 -> #DIV/0!
D13: 45992 | G13: =E13/F13 -> #DIV/0!
D14: TOTAL AÑO | E14: =SUM(E2:E13) -> 45 | F14: =SUM(F2:F13) -> 47 | G14: =E14/F14 -> 0.95744681

Sheet 6,1 CUMPLIMIENTO GES ONCO
A1: N° COMGES | B1: INDICADOR | C1: N° INDICADOR | D1: MES | E1: NUMERADOR | F1: DENOMINADOR | G1: Resultado indicador
D2: 46023 | E2: 152 | F2: 160 | G2: =IFERROR(E2/F2,"") -> 0.95
D3: 46054 | E3: 187 | F3: 199 | G3: =IFERROR(E3/F3,"") -> 0.93969849
D4: 46082 | E4: 208 | F4: 258 | G4: =IFERROR(E4/F4,"") -> 0.80620155
D5: 46113 | E5: 208 | F5: 285 | G5: =IFERROR(E5/F5,"") -> 0.72982456
D6: 46143 | E6: 361 | F6: 431 | G6: =IFERROR(E6/F6,"") -> 0.83758701
D7: 46174 | E7: 354 | F7: 452 | G7: =IFERROR(E7/F7,"") -> 0.78318584
D8: 46204 | G8: =IFERROR(E8/F8,"")
D9: 46235 | G9: =IFERROR(E9/F9,"")
D10: 46266 | G10: =IFERROR(E10/F10,"")
D11: 46296 | G11: =IFERROR(E11/F11,"")
D12: 46327 | G12: =IFERROR(E12/F12,"")
D13: 46357 | G13: =IFERROR(E13/F13,"")
D14: TOTAL AÑO | E14: =E7 -> 354 | F14: =F7 -> 452 | G14: =G7 -> 0.78318584

Sheet 5,2 SUPERV ECPRI
A1: N° INDICADOR | B1: MES | C1: ECPRI SUPERVISADOS | D1: ECPRI REPORTADOS | E1: Meta | F1: Resultado indicador
A2: 5.2 | B2: 46023 | C2: 0 | D2: 0 | E2: >80% | F2: =C2/D2 -> #DIV/0!
A3: 5.2 | B3: 46054 | C3: 0 | D3: 0 | E3: >80% | F3: =C3/D3 -> #DIV/0!
A4: 5.2 | B4: 46082 | C4: 0 | D4: 0 | E4: >80% | F4: =C4/D4 -> #DIV/0!
A5: 5.2 | B5: 46113 | C5: 0 | D5: 0 | E5: >80% | F5: =C5/D5 -> #DIV/0!
A6: 5.2 | B6: 46143 | C6: 0 | D6: 0 | E6: >80% | F6: =C6/D6 -> #DIV/0!
A7: 5.2 | B7: 46174 | C7: 0 | D7: 0 | E7: >80% | F7: =C7/D7 -> #DIV/0!
A8: 5.2 | B8: 46204 | C8: 0 | D8: 0 | E8: >80% | F8: =C8/D8 -> #DIV/0!
A9: 5.2 | B9: 46235 | E9: >80% | F9: =C9/D9 -> #DIV/0!
A10: 5.2 | B10: 46266 | E10: >80% | F10: =C10/D10 -> #DIV/0!
A11: 5.2 | B11: 46296 | E11: >80% | F11: =C11/D11 -> #DIV/0!
A12: 5.2 | B12: 46327 | E12: >80% | F12: =C12/D12 -> #DIV/0!
A13: 5.2 | B13: 46357 | E13: >80% | F13: =C13/D13 -> #DIV/0!
A14: 5.2 | B14: TOTAL AÑO | C14: =SUM(C2:C13) -> 0 | D14: =SUM(D2:D13) -> 0 | E14: >80% | F14: =C14/D14 -> #DIV/0!

Sheet 4,7 PROCED DISCIPLINARIOS
A1: 4,7 Procedimientos disciplinarios por violencia, acoso laboral y sexual cerrados en los plazos estipulados por ley
A2: META:50%
A3: MES | B3: Número de procedimientos VALS cerrados en plazo legal | C3: Número total de procedimientos VALS | D3: Meta | E3: Resultado indicador
A4: 46023 | D4: =B4/C4 -> #DIV/0! | E4: =B4/C4 -> #DIV/0!
A5: 46054 | E5: =B5/C5 -> #DIV/0!
A6: 46082 | E6: =B6/C6 -> #DIV/0!
A7: 46113 | E7: =B7/C7 -> #DIV/0!
A8: 46143 | E8: =B8/C8 -> #DIV/0!
A9: 46174 | E9: =B9/C9 -> #DIV/0!
A10: 46204 | E10: =B10/C10 -> #DIV/0!
A11: 46235 | E11: =B11/C11 -> #DIV/0!
A12: 46266 | E12: =B12/C12 -> #DIV/0!
A13: 46296 | E13: =B13/C13 -> #DIV/0!
A14: 46327 | E14: =B14/C14 -> #DIV/0!
A15: 46357 | E15: =B15/C15 -> #DIV/0!
A16: TOTAL AÑO | B16: =SUM(B4:B15) -> 0 | C16: =SUM(C4:C15) -> 0 | E16: =B16/C16 -> #DIV/0!

Sheet 4,6 IND AUSENTISMO
A1: MES | B1: INDICE AUSENTISMO 2025 | C1: INDICE AUSENTISMO 2026 | D1: VARIACION | E1: META
A2: 46023 | E2: DISMINUIR O MANTENER 21,2
A3: 46054
A4: 46082
A5: 46113
A6: 46143 | B6: 10.2 | C6: 8.1 | D6: =C6-B6 -> -2.1
A7: 46174 | D7: =C7-B7 -> 0
A8: 46204 | D8: =C8-B8 -> 0
A9: 46235 | D9: =C9-B9 -> 0
A10: 46266 | D10: =C10-B10 -> 0
A11: 46296 | D11: =C11-B11 -> 0
A12: 46327 | D12: =C12-B12 -> 0
A13: 46357 | D13: =C13-B13 -> 0
A14: TOTAL AÑO | D14: =C14-B14 -> 0
A15: 4,6 Indice de ausentismo laboral por Licencia medica curativa
A16: META:

Sheet 4,5 GASTO PERSONAS NATURALES 
A1: MES | B1: GASTO CONVENIO PERSONAS NATURALES | C1: GLOSA CONVENIO PERSONAS NATURALES | D1: Meta | E1: Resultado indicador
A2: 46023 | D2: <1 | E2: =IFERROR(B2/C2,"")
A3: 46054 | E3: =IFERROR(B3/C3,"")
A4: 46082 | B4: 3223649 | C4: 3876000 | E4: =IFERROR(B4/C4,"") -> 0.83169479
A5: 46113 | E5: =IFERROR(B5/C5,"")
A6: 46143 | E6: =IFERROR(B6/C6,"")
A7: 46174 | E7: =IFERROR(B7/C7,"")
A8: 46204 | E8: =IFERROR(B8/C8,"")
A9: 46235 | E9: =IFERROR(B9/C9,"")
A10: 46266 | E10: =IFERROR(B10/C10,"")
A11: 46296 | E11: =IFERROR(B11/C11,"")
A12: 46327 | E12: =IFERROR(B12/C12,"")
A13: 46357 | E13: =IFERROR(B13/C13,"")
A14: TOTAL AÑO | B14: =SUM(B2:B13) -> 3223649 | C14: =SUM(C2:C13) -> 3876000 | E14: =IFERROR(B14/C14,"") -> 0.83169479

Sheet 4,4 GESTION DE DESASTRES
A1: 4,4 Hospitales con implementación de Gestión de Riesgo de Desastres
A2: META: 66,6%
A3: 2 de 3 de las siguientes acciones: | C3: 45809 | D3: 45839 | E3: 45870 | F3: 45901 | G3: 45931 | H3: 45962 | I3: 45992
A4: 1. | B4: Hospitales con Plan de Telecomunicaciones de emergencia actualizado | J4: en proceso
A5: 2. | B5: Encargados de gestión del riesgo con acceso a Módulo de Emergencia MIDAS | E5: cumplido
A6: 3. | B6: Hospitales con fichas de capacidades identificadas y actualizadas | E6: cumplido
A8: Requisito: Cumplir con el 100% de las siguientes 2 acciones tanto en el Servicio de Salud como en los hospitales. | C8: 45809 | D8: 45839 | E8: 45870 | F8: 45901 | G8: 45931 | H8: 45962 | I8: 45992
A9: 1. | B9: Servicios de Salud y Hospitales con Encargado de Gestión del Riesgo de Desastre | E9: cumplido
A10: 2. | B10: Servicios de Salud y Hospitales con Plan de Respuesta actualizado | E10: cumplido
B12: Verificables
B13: Las acciones solicitadas son para verificar el nivel de compromiso con la GRD en los SS.
B14: Se deben remitir las resoluciones con nombramientos para GRD y MIDAS.
B15: Relleno de las fichas de capacidades de los Hospitales en la plataforma MIDAS.
B16: Recepción de Resoluciones con planes de Respuesta y plan de telecomunicaciones.
B17: Al final del periodo se remitirá a los Servicios de Salud el nivel de cumplimiento de las distintas acciones solicitadas.
A19: ⁻
A21: ⁻

Sheet 3,2 EG TRANSIT  GES
A1: N° COMGES | B1: INDICADOR | C1: N° INDICADOR | D1: MES | E1: NUMERADOR | F1: DENOMINADOR | G1: Meta | H1: Resultado indicador | I1: Resultado indicador
A2: 3.- Mejora de los tiempos de espera. | B2: 3.2 Resolución de garantías exceptuadas transitorias acumuladas sin prestación otorgada. | C2: 3.2 | D2: 46023 | G2: =E2/F2 -> #DIV/0! | H2: =E2/F2 -> #DIV/0!
A3: 3.- Mejora de los tiempos de espera. | B3: 3.2 Resolución de garantías exceptuadas transitorias acumuladas sin prestación otorgada. | C3: 3.2 | D3: 46054 | H3: =E3/F3 -> #DIV/0!
A4: 3.- Mejora de los tiempos de espera. | B4: 3.2 Resolución de garantías exceptuadas transitorias acumuladas sin prestación otorgada. | C4: 3.2 | D4: 46082 | H4: =E4/F4 -> #DIV/0!
A5: 3.- Mejora de los tiempos de espera. | B5: 3.2 Resolución de garantías exceptuadas transitorias acumuladas sin prestación otorgada. | C5: 3.2 | D5: 46113 | E5: 60 | F5: 183 | H5: =E5/F5 -> 0.32786885
A6: 3.- Mejora de los tiempos de espera. | B6: 3.2 Resolución de garantías exceptuadas transitorias acumuladas sin prestación otorgada. | C6: 3.2 | D6: 46143 | H6: =E6/F6 -> #DIV/0!
A7: 3.- Mejora de los tiempos de espera. | B7: 3.2 Resolución de garantías exceptuadas transitorias acumuladas sin prestación otorgada. | C7: 3.2 | D7: 46174 | H7: =E7/F7 -> #DIV/0!
A8: 3.- Mejora de los tiempos de espera. | B8: 3.2 Resolución de garantías exceptuadas transitorias acumuladas sin prestación otorgada. | C8: 3.2 | D8: 46204 | H8: =E8/F8 -> #DIV/0!
A9: 3.- Mejora de los tiempos de espera. | B9: 3.2 Resolución de garantías exceptuadas transitorias acumuladas sin prestación otorgada. | C9: 3.2 | D9: 46235 | H9: =E9/F9 -> #DIV/0!
A10: 3.- Mejora de los tiempos de espera. | B10: 3.2 Resolución de garantías exceptuadas transitorias acumuladas sin prestación otorgada. | C10: 3.2 | D10: 46266 | H10: =E10/F10 -> #DIV/0!
A11: 3.- Mejora de los tiempos de espera. | B11: 3.2 Resolución de garantías exceptuadas transitorias acumuladas sin prestación otorgada. | C11: 3.2 | D11: 46296 | H11: =E11/F11 -> #DIV/0!
A12: 3.- Mejora de los tiempos de espera. | B12: 3.2 Resolución de garantías exceptuadas transitorias acumuladas sin prestación otorgada. | C12: 3.2 | D12: 46327 | H12: =E12/F12 -> #DIV/0!
A13: 3.- Mejora de los tiempos de espera. | B13: 3.2 Resolución de garantías exceptuadas transitorias acumuladas sin prestación otorgada. | C13: 3.2 | D13: 46357 | H13: =E13/F13 -> #DIV/0!
A14: 3.- Mejora de los tiempos de espera. | B14: 3.2 Resolución de garantías exceptuadas transitorias acumuladas sin prestación otorgada. | C14: 3.2 | D14: TOTAL AÑO | E14: =SUM(E2:E13) -> 60 | F14: =SUM(F2:F13) -> 183 | H14: =E14/F14 -> 0.32786885

Sheet 3,1 CUMPLIMIENTO GES
A1: N° COMGES | B1: INDICADOR | C1: N° INDICADOR | D1: MES | E1: NUMERADOR | F1: DENOMINADOR | G1: Meta | H1: Resultado indicador
A2: 3.- Mejora de los tiempos de espera. | B2: 3.1 Cumplimiento de Garantías explícitas en Salud (GES) en la red. | D2: 46023 | E2: ='[3]6 GES'!H2 -> 2259 | F2: ='[3]6 GES'!I2 -> 2377 | G2: 0.995 | H2: =IFERROR(E2/F2,"") -> 0.95035759
A3: 3.- Mejora de los tiempos de espera. | B3: 3.1 Cumplimiento de Garantías explícitas en Salud (GES) en la red. | D3: 46054 | E3: ='[3]6 GES'!H3 -> 2920 | F3: ='[3]6 GES'!I3 -> 3095 | G3: 0.995 | H3: =IFERROR(E3/F3,"") -> 0.94345719 | I3: 45975 | J3: num | L3: denomi
A4: 3.- Mejora de los tiempos de espera. | B4: 3.1 Cumplimiento de Garantías explícitas en Salud (GES) en la red. | D4: 46082 | E4: ='[3]6 GES'!H4 -> 3387 | F4: ='[3]6 GES'!I4 -> 3758 | G4: 0.995 | H4: =IFERROR(E4/F4,"") -> 0.90127728 | I4: cumplidas | J4: 8733 | K4: 395 | L4: retrasadas
A5: 3.- Mejora de los tiempos de espera. | B5: 3.1 Cumplimiento de Garantías explícitas en Salud (GES) en la red. | D5: 46113 | E5: ='[3]6 GES'!H5 -> 4820 | F5: ='[3]6 GES'!I5 -> 5273 | G5: 0.995 | H5: =IFERROR(E5/F5,"") -> 0.91409065 | I5: eg | J5: 228 | L5: incumplidas no at
A6: 3.- Mejora de los tiempos de espera. | B6: 3.1 Cumplimiento de Garantías explícitas en Salud (GES) en la red. | D6: 46143 | E6: 5821 | F6: 6299 | G6: 0.995 | H6: =IFERROR(E6/F6,"") -> 0.92411494 | I6: incumplidas at | J6: 2157
A7: 3.- Mejora de los tiempos de espera. | B7: 3.1 Cumplimiento de Garantías explícitas en Salud (GES) en la red. | D7: 46174 | E7: 6399 | F7: 6979 | H7: =IFERROR(E7/F7,"") -> 0.91689354 | J7: =SUM(J4:J6) -> 11118 | K7: =SUM(K4:K6) -> 395 | L7: =SUM(J7:K7) -> 11513
A8: 3.- Mejora de los tiempos de espera. | B8: 3.1 Cumplimiento de Garantías explícitas en Salud (GES) en la red. | D8: 46204 | E8: ='[3]6 GES'!H8 -> 0 | F8: ='[3]6 GES'!I8 -> 0 | H8: =IFERROR(E8/F8,"")
A9: 3.- Mejora de los tiempos de espera. | B9: 3.1 Cumplimiento de Garantías explícitas en Salud (GES) en la red. | D9: 46235 | E9: ='[3]6 GES'!H9 -> 0 | F9: ='[3]6 GES'!I9 -> 0 | H9: =IFERROR(E9/F9,"")
A10: 3.- Mejora de los tiempos de espera. | B10: 3.1 Cumplimiento de Garantías explícitas en Salud (GES) en la red. | D10: 46266 | E10: ='[3]6 GES'!H10 -> 0 | F10: ='[3]6 GES'!I10 -> 0 | H10: =IFERROR(E10/F10,"")
A11: 3.- Mejora de los tiempos de espera. | B11: 3.1 Cumplimiento de Garantías explícitas en Salud (GES) en la red. | D11: 46296 | E11: ='[3]6 GES'!H11 -> 0 | F11: ='[3]6 GES'!I11 -> 0 | H11: =IFERROR(E11/F11,"")
A12: 3.- Mejora de los tiempos de espera. | B12: 3.1 Cumplimiento de Garantías explícitas en Salud (GES) en la red. | D12: 46327 | E12: ='[3]6 GES'!H12 -> 0 | F12: ='[3]6 GES'!I12 -> 0 | H12: =IFERROR(E12/F12,"")
A13: 3.- Mejora de los tiempos de espera. | B13: 3.1 Cumplimiento de Garantías explícitas en Salud (GES) en la red. | D13: 46357 | E13: ='[3]6 GES'!H13 -> 0 | F13: ='[3]6 GES'!I13 -> 0 | H13: =IFERROR(E13/F13,"")
A14: 3.- Mejora de los tiempos de espera. | B14: 3.1 Cumplimiento de Garantías explícitas en Salud (GES) en la red. | D14: TOTAL AÑO | E14: =E7 -> 6399 | F14: =F7 -> 6979 | G14: =E14/F14 -> 0.91689354 | H14: =H6 -> 0.92411494

Sheet 2,10 POT DONANTES
A1: N° COMGES | B1: INDICADOR | C1: N° INDICADOR | D1: MES | E1: NUMERADOR | F1: DENOMINADOR | G1: Meta | H1: Resultado indicador | I1: Resultado indicador
C2: 2.1 | D2: 46023 | H2: =E2/F2 -> #DIV/0!
C3: 2.1 | D3: 46054 | H3: =E3/F3 -> #DIV/0!
C4: 2.1 | D4: 46082 | H4: =E4/F4 -> #DIV/0!
C5: 2.1 | D5: 46113 | H5: =E5/F5 -> #DIV/0!
C6: 2.1 | D6: 46143 | H6: =E6/F6 -> #DIV/0!
C7: 2.1 | D7: 46174 | H7: =E7/F7 -> #DIV/0!
C8: 2.1 | D8: 46204 | H8: =E8/F8 -> #DIV/0!
C9: 2.1 | D9: 46235 | H9: =E9/F9 -> #DIV/0!
C10: 2.1 | D10: 46266 | H10: =E10/F10 -> #DIV/0!
C11: 2.1 | D11: 46296 | H11: =E11/F11 -> #DIV/0!
C12: 2.1 | D12: 46327 | H12: =E12/F12 -> #DIV/0!
C13: 2.1 | D13: 46357 | H13: =E13/F13 -> #DIV/0!
C14: 2.1 | D14: TOTAL AÑO | E14: =SUM(E2:E13) -> 0 | F14: =SUM(F2:F13) -> 0 | H14: =E14/F14 -> #DIV/0!

Sheet 2,8 PAC PD 
A1: N° COMGES | B1: INDICADOR | C1: N° INDICADOR | D1: MES | E1: NUMERADOR | F1: DENOMINADOR | G1: Meta | H1: Resultado indicador
C2: 2.8 | D2: 46023 | E2: 8 | F2: 29 | G2: >=20% | H2: =E2/F2 -> 0.27586207
C3: 2.8 | D3: 46054 | E3: 9 | F3: 30 | G3: >=20% | H3: =E3/F3 -> 0.3
C4: 2.8 | D4: 46082 | E4: 9 | F4: 34 | G4: >=20% | H4: =E4/F4 -> 0.26470588
C5: 2.8 | D5: 46113 | E5: 10 | F5: 36 | G5: >=20% | H5: =E5/F5 -> 0.27777778
C6: 2.8 | D6: 46143 | E6: 12 | F6: 42 | G6: >=20% | H6: =E6/F6 -> 0.28571429
C7: 2.8 | D7: 46174 | G7: >=20% | H7: =E7/F7 -> #DIV/0!
C8: 2.8 | D8: 46204 | G8: >=20% | H8: =E8/F8 -> #DIV/0!
C9: 2.8 | D9: 46235 | G9: >=20% | H9: =E9/F9 -> #DIV/0!
C10: 2.8 | D10: 46266 | G10: >=20% | H10: =E10/F10 -> #DIV/0!
C11: 2.8 | D11: 46296 | G11: >=20% | H11: =E11/F11 -> #DIV/0!
C12: 2.8 | D12: 46327 | G12: >=20% | H12: =E12/F12 -> #DIV/0!
C13: 2.8 | D13: 46357 | G13: >=20% | H13: =E13/F13 -> #DIV/0!
C14: 2.8 | D14: TOTAL AÑO | E14: =SUM(E2:E13) -> 48 | F14: =SUM(F2:F13) -> 171 | G14: >=20% | H14: =E14/F14 -> 0.28070175

Sheet 2,7 FAV EN IRC
A1: N° COMGES | B1: INDICADOR | C1: N° INDICADOR | D1: MES | E1: NUMERADOR | F1: DENOMINADOR | G1: Meta | H1: Resultado indicador
C2: 2.7 | D2: 46023 | G2: 0.7 | H2: =E2/F2 -> #DIV/0!
C3: 2.7 | D3: 46054 | G3: 0.7 | H3: =E3/F3 -> #DIV/0!
C4: 2.7 | D4: 46082 | E4: 113 | F4: 195 | G4: 0.7 | H4: =E4/F4 -> 0.57948718
C5: 2.7 | D5: 46113 | E5: 115 | F5: 201 | G5: 0.7 | H5: =E5/F5 -> 0.5721393
C6: 2.7 | D6: 46143 | G6: 0.7 | H6: =E6/F6 -> #DIV/0!
C7: 2.7 | D7: 46174 | G7: 0.7 | H7: =E7/F7 -> #DIV/0!
C8: 2.7 | D8: 46204 | G8: 0.7 | H8: =E8/F8 -> #DIV/0!
C9: 2.7 | D9: 46235 | G9: 0.7 | H9: =E9/F9 -> #DIV/0!
C10: 2.7 | D10: 46266 | G10: 0.7 | H10: =E10/F10 -> #DIV/0!
C11: 2.7 | D11: 46296 | G11: 0.7 | H11: =E11/F11 -> #DIV/0!
C12: 2.7 | D12: 46327 | G12: 0.7 | H12: =E12/F12 -> #DIV/0!
C13: 2.7 | D13: 46357 | G13: 0.7 | H13: =E13/F13 -> #DIV/0!
C14: 2.7 | D14: TOTAL AÑO | E14: =SUM(E2:E13) -> 228 | F14: =SUM(F2:F13) -> 396 | G14: 0.7 | H14: =E14/F14 -> 0.57575758

Sheet 2.3 CESAREA
A1: N° COMGES | B1: INDICADOR | C1: N° INDICADOR | D1: MES | E1: NUMERADOR | F1: DENOMINADOR | G1: Meta | H1: Resultado indicador | I1: Resultado indicador
A2: 2.- Reducir las complicaciones de salud mediante estrategias de prevención, diagnóstico y tratamiento. | B2: 2.3 Tasa global de cesárea. | C2: 2.3 | D2: 46023 | E2: =[4]A24!$C$15+[4]A24!$C$16 -> 26 | F2: =[4]A24!$C$13+[4]A24!$C$14+[4]A24!$C$15+[4]A24!$C$16 -> 68 | G2: <39,3% | H2: =E2/F2 -> 0.38235294
A3: 2.- Reducir las complicaciones de salud mediante estrategias de prevención, diagnóstico y tratamiento. | B3: 2.3 Tasa global de cesárea. | C3: 2.3 | D3: 46054 | E3: =[5]A24!$C$15+[5]A24!$C$16 -> 37 | F3: =[5]A24!$C$13+[5]A24!$C$14+[5]A24!$C$15+[5]A24!$C$16 -> 75 | G3: <39,3% | H3: =E3/F3 -> 0.49333333
A4: 2.- Reducir las complicaciones de salud mediante estrategias de prevención, diagnóstico y tratamiento. | B4: 2.3 Tasa global de cesárea. | C4: 2.3 | D4: 46082 | E4: =[6]A24!$C$15+[6]A24!$C$16 -> 39 | F4: =[6]A24!$C$13+[6]A24!$C$14+[6]A24!$C$15+[6]A24!$C$16 -> 84 | G4: <39,3% | H4: =E4/F4 -> 0.46428571
A5: 2.- Reducir las complicaciones de salud mediante estrategias de prevención, diagnóstico y tratamiento. | B5: 2.3 Tasa global de cesárea. | C5: 2.3 | D5: 46113 | E5: =[7]A24!$C$15+[7]A24!$C$16 -> 39 | F5: =[7]A24!$C$13+[7]A24!$C$14+[7]A24!$C$15+[7]A24!$C$16 -> 93 | G5: <39,3% | H5: =E5/F5 -> 0.41935484 | K5: % Cesareas 2025
A6: 2.- Reducir las complicaciones de salud mediante estrategias de prevención, diagnóstico y tratamiento. | B6: 2.3 Tasa global de cesárea. | C6: 2.3 | D6: 46143 | E6: =[8]A24!$C$15+[8]A24!$C$16 -> 35 | F6: =[8]A24!$C$13+[8]A24!$C$14+[8]A24!$C$15+[8]A24!$C$16 -> 77 | G6: <39,3% | H6: =E6/F6 -> 0.45454545 | K6: 0.433 | L6: 0.04 | M6: =K6-L6 -> 0.393
A7: 2.- Reducir las complicaciones de salud mediante estrategias de prevención, diagnóstico y tratamiento. | B7: 2.3 Tasa global de cesárea. | C7: 2.3 | D7: 46174 | E7: =[9]A24!$C$15+[9]A24!$C$16 -> 55 | F7: =[9]A24!$C$13+[9]A24!$C$14+[9]A24!$C$15+[9]A24!$C$16 -> 96 | G7: <39,3% | H7: =E7/F7 -> 0.57291667
A8: 2.- Reducir las complicaciones de salud mediante estrategias de prevención, diagnóstico y tratamiento. | B8: 2.3 Tasa global de cesárea. | C8: 2.3 | D8: 46204 | G8: <39,3% | H8: =E8/F8 -> #DIV/0!
A9: 2.- Reducir las complicaciones de salud mediante estrategias de prevención, diagnóstico y tratamiento. | B9: 2.3 Tasa global de cesárea. | C9: 2.3 | D9: 46235 | G9: <39,3% | H9: =E9/F9 -> #DIV/0!
A10: 2.- Reducir las complicaciones de salud mediante estrategias de prevención, diagnóstico y tratamiento. | B10: 2.3 Tasa global de cesárea. | C10: 2.3 | D10: 46266 | G10: <39,3% | H10: =E10/F10 -> #DIV/0!
A11: 2.- Reducir las complicaciones de salud mediante estrategias de prevención, diagnóstico y tratamiento. | B11: 2.3 Tasa global de cesárea. | C11: 2.3 | D11: 46296 | G11: <39,3% | H11: =E11/F11 -> #DIV/0!
A12: 2.- Reducir las complicaciones de salud mediante estrategias de prevención, diagnóstico y tratamiento. | B12: 2.3 Tasa global de cesárea. | C12: 2.3 | D12: 46327 | G12: <39,3% | H12: =E12/F12 -> #DIV/0!
A13: 2.- Reducir las complicaciones de salud mediante estrategias de prevención, diagnóstico y tratamiento. | B13: 2.3 Tasa global de cesárea. | C13: 2.3 | D13: 46357 | G13: <39,3% | H13: =E13/F13 -> #DIV/0!
A14: 2.- Reducir las complicaciones de salud mediante estrategias de prevención, diagnóstico y tratamiento. | B14: 2.3 Tasa global de cesárea. | C14: 2.3 | D14: TOTAL AÑO | E14: =SUM(E2:E13) -> 231 | F14: =SUM(F2:F13) -> 493 | G14: <39,3% | H14: =E14/F14 -> 0.46855984 | I14: =(H14-43.3%)/43.3% -> 0.082124337

Sheet 1,15 CAMAS DISPONIBLES
A1: N° COMGES | B1: INDICADOR | C1: N° INDICADOR | D1: MES | E1: CAMAS DISPONIBLES | F1: DIAS CALENDARIO | G1: CAMAS DOTACION | H1: CAMAS POR RESOLUCION*DIAS CALENDARIO | I1: Meta | J1: Resultado indicador | K1: Resultado indicador
A2: 1.- Mejorar la eficiencia en la gestión de procesos asistenciales. | B2: 1.14 Camas disponibles respecto de la dotación vigente. | C2: 1.15 | D2: 46023 | E2: 3751 | F2: 31 | G2: 125 | H2: =F2*G2 -> 3875 | I2: >95% | J2: =E2/H2 -> 0.968 | K2: =E2/F2 -> 121
A3: 1.- Mejorar la eficiencia en la gestión de procesos asistenciales. | B3: 1.14 Camas disponibles respecto de la dotación vigente. | C3: 1.15 | D3: 46054 | E3: 3388 | F3: 28 | G3: 125 | H3: =F3*G3 -> 3500 | I3: >95% | J3: =E3/H3 -> 0.968 | K3: =E3/F3 -> 121
A4: 1.- Mejorar la eficiencia en la gestión de procesos asistenciales. | B4: 1.14 Camas disponibles respecto de la dotación vigente. | C4: 1.15 | D4: 46082 | E4: 3751 | F4: 31 | G4: 125 | H4: =F4*G4 -> 3875 | I4: >95% | J4: =E4/H4 -> 0.968 | K4: =E4/F4 -> 121
A5: 1.- Mejorar la eficiencia en la gestión de procesos asistenciales. | B5: 1.14 Camas disponibles respecto de la dotación vigente. | C5: 1.15 | D5: 46113 | E5: 3631 | F5: 30 | G5: 125 | H5: =F5*G5 -> 3750 | I5: >95% | J5: =E5/H5 -> 0.96826667 | K5: =E5/F5 -> 121.03333
A6: 1.- Mejorar la eficiencia en la gestión de procesos asistenciales. | B6: 1.14 Camas disponibles respecto de la dotación vigente. | C6: 1.15 | D6: 46143 | E6: 3753 | F6: 31 | G6: 125 | H6: =F6*G6 -> 3875 | I6: >95% | J6: =E6/H6 -> 0.96851613 | K6: =E6/F6 -> 121.06452
A7: 1.- Mejorar la eficiencia en la gestión de procesos asistenciales. | B7: 1.14 Camas disponibles respecto de la dotación vigente. | C7: 1.15 | D7: 46174 | E7: 3772 | F7: 30 | G7: 125 | H7: =F7*G7 -> 3750 | I7: >95% | J7: =E7/H7 -> 1.0058667 | K7: =E7/F7 -> 125.73333
A8: 1.- Mejorar la eficiencia en la gestión de procesos asistenciales. | B8: 1.14 Camas disponibles respecto de la dotación vigente. | C8: 1.15 | D8: 46204 | H8: =F8*G8 -> 0 | I8: >95% | J8: =E8/H8 -> #DIV/0!
A9: 1.- Mejorar la eficiencia en la gestión de procesos asistenciales. | B9: 1.14 Camas disponibles respecto de la dotación vigente. | C9: 1.15 | D9: 46235 | H9: =F9*G9 -> 0 | I9: >95% | J9: =E9/H9 -> #DIV/0!
A10: 1.- Mejorar la eficiencia en la gestión de procesos asistenciales. | B10: 1.14 Camas disponibles respecto de la dotación vigente. | C10: 1.15 | D10: 46266 | H10: =F10*G10 -> 0 | I10: >95% | J10: =E10/H10 -> #DIV/0!
A11: 1.- Mejorar la eficiencia en la gestión de procesos asistenciales. | B11: 1.14 Camas disponibles respecto de la dotación vigente. | C11: 1.15 | D11: 46296 | H11: =F11*G11 -> 0 | I11: >95% | J11: =E11/H11 -> #DIV/0!
A12: 1.- Mejorar la eficiencia en la gestión de procesos asistenciales. | B12: 1.14 Camas disponibles respecto de la dotación vigente. | C12: 1.15 | D12: 46327 | H12: =F12*G12 -> 0 | I12: >95% | J12: =E12/H12 -> #DIV/0!
A13: 1.- Mejorar la eficiencia en la gestión de procesos asistenciales. | B13: 1.14 Camas disponibles respecto de la dotación vigente. | C13: 1.15 | D13: 46357 | H13: =F13*G13 -> 0 | I13: >95% | J13: =E13/H13 -> #DIV/0!
A14: 1.- Mejorar la eficiencia en la gestión de procesos asistenciales. | B14: 1.14 Camas disponibles respecto de la dotación vigente. | C14: 1.15 | D14: TOTAL AÑO | E14: =SUM(E2:E13) -> 22046 | F14: =SUM(F2:F13) -> 181 | G14: 125 | H14: =SUM(H2:H13) -> 22625 | I14: >95% | J14: =E14/H14 -> 0.97440884

Sheet 1,13 HODOM 
A1: N° COMGES | B1: INDICADOR | C1: N° INDICADOR | D1: MES | E1: NUMERADOR | F1: DENOMINADOR | G1: Meta | H1: Resultado indicador | I1: Resultado indicador
A2: 1.- Mejorar la eficiencia en la gestión de procesos asistenciales. | B2: 1.16 Días de estada en Hospitalización Domiciliaria. | C2: 1.13 | D2: 46023 | E2: =[4]A21!$C$33 -> 504 | F2: =[4]A21!$C$32 -> 61 | G2: <8,5% | H2: =E2/F2 -> 8.2622951
A3: 1.- Mejorar la eficiencia en la gestión de procesos asistenciales. | B3: 1.16 Días de estada en Hospitalización Domiciliaria. | C3: 1.13 | D3: 46054 | E3: =[5]A21!$C$33 -> 556 | F3: =[5]A21!$C$32 -> 50 | G3: <8,5% | H3: =E3/F3 -> 11.12
A4: 1.- Mejorar la eficiencia en la gestión de procesos asistenciales. | B4: 1.16 Días de estada en Hospitalización Domiciliaria. | C4: 1.13 | D4: 46082 | E4: =[6]A21!$C$33 -> 538 | F4: =[6]A21!$C$32 -> 56 | G4: <8,5% | H4: =E4/F4 -> 9.6071429
A5: 1.- Mejorar la eficiencia en la gestión de procesos asistenciales. | B5: 1.16 Días de estada en Hospitalización Domiciliaria. | C5: 1.13 | D5: 46113 | E5: =[7]A21!$C$33 -> 433 | F5: =[7]A21!$C$32 -> 51 | G5: <8,5% | H5: =E5/F5 -> 8.4901961
A6: 1.- Mejorar la eficiencia en la gestión de procesos asistenciales. | B6: 1.16 Días de estada en Hospitalización Domiciliaria. | C6: 1.13 | D6: 46143 | E6: =[8]A21!$C$33 -> 531 | F6: =[8]A21!$C$32 -> 57 | G6: <8,5% | H6: =E6/F6 -> 9.3157895
A7: 1.- Mejorar la eficiencia en la gestión de procesos asistenciales. | B7: 1.16 Días de estada en Hospitalización Domiciliaria. | C7: 1.13 | D7: 46174 | E7: =[9]A21!$C$33 -> 585 | F7: =[9]A21!$C$32 -> 66 | G7: <8,5% | H7: =E7/F7 -> 8.8636364
A8: 1.- Mejorar la eficiencia en la gestión de procesos asistenciales. | B8: 1.16 Días de estada en Hospitalización Domiciliaria. | C8: 1.13 | D8: 46204 | G8: <8,5% | H8: =E8/F8 -> #DIV/0!
A9: 1.- Mejorar la eficiencia en la gestión de procesos asistenciales. | B9: 1.16 Días de estada en Hospitalización Domiciliaria. | C9: 1.13 | D9: 46235 | G9: <8,5% | H9: =E9/F9 -> #DIV/0!
A10: 1.- Mejorar la eficiencia en la gestión de procesos asistenciales. | B10: 1.16 Días de estada en Hospitalización Domiciliaria. | C10: 1.13 | D10: 46266 | G10: <8,5% | H10: =E10/F10 -> #DIV/0!
A11: 1.- Mejorar la eficiencia en la gestión de procesos asistenciales. | B11: 1.16 Días de estada en Hospitalización Domiciliaria. | C11: 1.13 | D11: 46296 | G11: <8,5% | H11: =E11/F11 -> #DIV/0!
A12: 1.- Mejorar la eficiencia en la gestión de procesos asistenciales. | B12: 1.16 Días de estada en Hospitalización Domiciliaria. | C12: 1.13 | D12: 46327 | G12: <8,5% | H12: =E12/F12 -> #DIV/0!
A13: 1.- Mejorar la eficiencia en la gestión de procesos asistenciales. | B13: 1.16 Días de estada en Hospitalización Domiciliaria. | C13: 1.13 | D13: 46357 | G13: <8,5% | H13: =E13/F13 -> #DIV/0!
A14: 1.- Mejorar la eficiencia en la gestión de procesos asistenciales. | B14: 1.16 Días de estada en Hospitalización Domiciliaria. | C14: 1.13 | D14: TOTAL AÑO | E14: =SUM(E2:E13) -> 3147 | F14: =SUM(F2:F13) -> 341 | G14: <8,5% | H14: =E14/F14 -> 9.228739

Sheet 1,11 HOSP URG
A1: N° COMGES | B1: INDICADOR | C1: N° INDICADOR | D1: MES | E1: NUMERADOR | F1: DENOMINADOR | G1: Meta | H1: Resultado indicador | I1: Resultado indicador
A2: 1.- Mejorar la eficiencia en la gestión de procesos asistenciales. | B2: 1.11 Personas con indicación de hospitalización desde UEH, que acceden a cama de dotación en menos de 12 horas | C2: 1.11 | D2: 46023 | E2: =[4]A08!$C$107 -> 136 | F2: =[4]A08!$C$108+[4]A08!$C$109+[4]A08!$C$112+[4]A08!$C$107 -> 261 | G2: >85% | H2: =E2/F2 -> 0.5210728
A3: 1.- Mejorar la eficiencia en la gestión de procesos asistenciales. | B3: 1.11 Personas con indicación de hospitalización desde UEH, que acceden a cama de dotación en menos de 12 horas | C3: 1.11 | D3: 46054 | E3: =[5]A08!$C$107 -> 164 | F3: =[5]A08!$C$108+[5]A08!$C$109+[5]A08!$C$112+[5]A08!$C$107 -> 260 | G3: >85% | H3: =E3/F3 -> 0.63076923
A4: 1.- Mejorar la eficiencia en la gestión de procesos asistenciales. | B4: 1.11 Personas con indicación de hospitalización desde UEH, que acceden a cama de dotación en menos de 12 horas | C4: 1.11 | D4: 46082 | E4: =[6]A08!$C$107 -> 170 | F4: =[6]A08!$C$108+[6]A08!$C$109+[6]A08!$C$112+[6]A08!$C$107 -> 305 | G4: >85% | H4: =E4/F4 -> 0.55737705
A5: 1.- Mejorar la eficiencia en la gestión de procesos asistenciales. | B5: 1.11 Personas con indicación de hospitalización desde UEH, que acceden a cama de dotación en menos de 12 horas | C5: 1.11 | D5: 46113 | E5: =[7]A08!$C$107 -> 134 | F5: =[7]A08!$C$108+[7]A08!$C$109+[7]A08!$C$112+[7]A08!$C$107 -> 338 | G5: >85% | H5: =E5/F5 -> 0.3964497 | J5: =[7]A08!$C$112 -> 59
A6: 1.- Mejorar la eficiencia en la gestión de procesos asistenciales. | B6: 1.11 Personas con indicación de hospitalización desde UEH, que acceden a cama de dotación en menos de 12 horas | C6: 1.11 | D6: 46143 | E6: =[8]A08!$C$107 -> 152 | F6: =[8]A08!$C$108+[8]A08!$C$109+[8]A08!$C$112+[8]A08!$C$107 -> 346 | G6: >85% | H6: =E6/F6 -> 0.43930636 | J6: =[8]A08!$C$112 -> 79
A7: 1.- Mejorar la eficiencia en la gestión de procesos asistenciales. | B7: 1.11 Personas con indicación de hospitalización desde UEH, que acceden a cama de dotación en menos de 12 horas | C7: 1.11 | D7: 46174 | E7: =[9]A08!$C$107 -> 118 | F7: =[9]A08!$C$108+[9]A08!$C$109+[9]A08!$C$112+[9]A08!$C$107 -> 342 | G7: >85% | H7: =E7/F7 -> 0.34502924
A8: 1.- Mejorar la eficiencia en la gestión de procesos asistenciales. | B8: 1.11 Personas con indicación de hospitalización desde UEH, que acceden a cama de dotación en menos de 12 horas | C8: 1.11 | D8: 46204 | G8: >85% | H8: =E8/F8 -> #DIV/0!
A9: 1.- Mejorar la eficiencia en la gestión de procesos asistenciales. | B9: 1.11 Personas con indicación de hospitalización desde UEH, que acceden a cama de dotación en menos de 12 horas | C9: 1.11 | D9: 46235 | G9: >85% | H9: =E9/F9 -> #DIV/0!
A10: 1.- Mejorar la eficiencia en la gestión de procesos asistenciales. | B10: 1.11 Personas con indicación de hospitalización desde UEH, que acceden a cama de dotación en menos de 12 horas | C10: 1.11 | D10: 46266 | G10: >85% | H10: =E10/F10 -> #DIV/0!
A11: 1.- Mejorar la eficiencia en la gestión de procesos asistenciales. | B11: 1.11 Personas con indicación de hospitalización desde UEH, que acceden a cama de dotación en menos de 12 horas | C11: 1.11 | D11: 46296 | G11: >85% | H11: =E11/F11 -> #DIV/0!
A12: 1.- Mejorar la eficiencia en la gestión de procesos asistenciales. | B12: 1.11 Personas con indicación de hospitalización desde UEH, que acceden a cama de dotación en menos de 12 horas | C12: 1.11 | D12: 46327 | G12: >85% | H12: =E12/F12 -> #DIV/0!
A13: 1.- Mejorar la eficiencia en la gestión de procesos asistenciales. | B13: 1.11 Personas con indicación de hospitalización desde UEH, que acceden a cama de dotación en menos de 12 horas | C13: 1.11 | D13: 46357 | G13: >85% | H13: =E13/F13 -> #DIV/0!
A14: 1.- Mejorar la eficiencia en la gestión de procesos asistenciales. | B14: 1.11 Personas con indicación de hospitalización desde UEH, que acceden a cama de dotación en menos de 12 horas | C14: 1.11 | D14: TOTAL AÑO | E14: =SUM(E2:E13) -> 874 | F14: =SUM(F2:F13) -> 1852 | G14: >85% | H14: =E14/F14 -> 0.47192225

Sheet 1,10 AT C2
A1: N° COMGES | B1: INDICADOR | C1: N° INDICADOR | D1: MES | E1: NUMERADOR | F1: DENOMINADOR | G1: Meta | H1: Resultado indicador | I1: Resultado indicador
A2: 1.- Mejorar la eficiencia en la gestión de procesos asistenciales. | B2: 1.10 Personas categorizadas C2 atendidos oportunamente en las UEH adulto y pediátrico. | C2: 1.10 | D2: 46023 | E2: 342 | F2: =[4]A08!$B$62 -> 350 | G2: >90% | H2: =E2/F2 -> 0.97714286 | I2: 376
A3: 1.- Mejorar la eficiencia en la gestión de procesos asistenciales. | B3: 1.10 Personas categorizadas C2 atendidos oportunamente en las UEH adulto y pediátrico. | C3: 1.10 | D3: 46054 | E3: 332 | F3: =[5]A08!$B$62 -> 342 | G3: >90% | H3: =E3/F3 -> 0.97076023 | I3: 370
A4: 1.- Mejorar la eficiencia en la gestión de procesos asistenciales. | B4: 1.10 Personas categorizadas C2 atendidos oportunamente en las UEH adulto y pediátrico. | C4: 1.10 | D4: 46082 | E4: 338 | F4: =[6]A08!$B$62 -> 344 | G4: >90% | H4: =E4/F4 -> 0.98255814 | I4: 396
A5: 1.- Mejorar la eficiencia en la gestión de procesos asistenciales. | B5: 1.10 Personas categorizadas C2 atendidos oportunamente en las UEH adulto y pediátrico. | C5: 1.10 | D5: 46113 | E5: 327 | F5: =[7]A08!$B$62 -> 345 | G5: >90% | H5: =E5/F5 -> 0.94782609 | I5: 364
A6: 1.- Mejorar la eficiencia en la gestión de procesos asistenciales. | B6: 1.10 Personas categorizadas C2 atendidos oportunamente en las UEH adulto y pediátrico. | C6: 1.10 | D6: 46143 | E6: 291 | F6: =[8]A08!$B$62 -> 301 | G6: >90% | H6: =E6/F6 -> 0.96677741
A7: 1.- Mejorar la eficiencia en la gestión de procesos asistenciales. | B7: 1.10 Personas categorizadas C2 atendidos oportunamente en las UEH adulto y pediátrico. | C7: 1.10 | D7: 46174 | E7: 281 | F7: =[9]A08!$B$62 -> 291 | G7: >90% | H7: =E7/F7 -> 0.96563574
A8: 1.- Mejorar la eficiencia en la gestión de procesos asistenciales. | B8: 1.10 Personas categorizadas C2 atendidos oportunamente en las UEH adulto y pediátrico. | C8: 1.10 | D8: 46204 | G8: >90% | H8: =E8/F8 -> #DIV/0!
A9: 1.- Mejorar la eficiencia en la gestión de procesos asistenciales. | B9: 1.10 Personas categorizadas C2 atendidos oportunamente en las UEH adulto y pediátrico. | C9: 1.10 | D9: 46235 | G9: >90% | H9: =E9/F9 -> #DIV/0!
A10: 1.- Mejorar la eficiencia en la gestión de procesos asistenciales. | B10: 1.10 Personas categorizadas C2 atendidos oportunamente en las UEH adulto y pediátrico. | C10: 1.10 | D10: 46266 | G10: >90% | H10: =E10/F10 -> #DIV/0!
A11: 1.- Mejorar la eficiencia en la gestión de procesos asistenciales. | B11: 1.10 Personas categorizadas C2 atendidos oportunamente en las UEH adulto y pediátrico. | C11: 1.10 | D11: 46296 | G11: >90% | H11: =E11/F11 -> #DIV/0!
A12: 1.- Mejorar la eficiencia en la gestión de procesos asistenciales. | B12: 1.10 Personas categorizadas C2 atendidos oportunamente en las UEH adulto y pediátrico. | C12: 1.10 | D12: 46327 | G12: >90% | H12: =E12/F12 -> #DIV/0!
A13: 1.- Mejorar la eficiencia en la gestión de procesos asistenciales. | B13: 1.10 Personas categorizadas C2 atendidos oportunamente en las UEH adulto y pediátrico. | C13: 1.10 | D13: 46357 | G13: >90% | H13: =E13/F13 -> #DIV/0!
A14: 1.- Mejorar la eficiencia en la gestión de procesos asistenciales. | B14: 1.10 Personas categorizadas C2 atendidos oportunamente en las UEH adulto y pediátrico. | C14: 1.10 | D14: TOTAL AÑO | E14: =SUM(E2:E13) -> 1911 | F14: =SUM(F2:F13) -> 1973 | G14: >90% | H14: =E14/F14 -> 0.96857577 | I14: =I2+I3+I4+I5+I6+I7+I8+I9+I10+I11+I12+I13 -> 1506

Sheet 1,9 ABANDONO URG
A1: N° COMGES | B1: INDICADOR | C1: N° INDICADOR | D1: MES | E1: NUMERADOR | F1: DENOMINADOR | G1: Meta | H1: Resultado indicador | I1: Resultado indicador
A2: 1.- Mejorar la eficiencia en la gestión de procesos asistenciales. | B2: 1.9 Personas que abandonan durante el Proceso de Atención de Urgencia en las Unidades de Emergencia Hospitalaria Adulto y Pediátrica. | C2: 1.9 | D2: 46023 | E2: =F2-[4]A08!$B$12 -> 1137 | F2: =[4]A08!$AS$12 -> 4616 | G2: <10% | H2: =E2/F2 -> 0.24631716
A3: 1.- Mejorar la eficiencia en la gestión de procesos asistenciales. | B3: 1.9 Personas que abandonan durante el Proceso de Atención de Urgencia en las Unidades de Emergencia Hospitalaria Adulto y Pediátrica. | C3: 1.9 | D3: 46054 | E3: =F3-[5]A08!$B$12 -> 1143 | F3: =[5]A08!$AS$12 -> 4507 | G3: <10% | H3: =E3/F3 -> 0.2536055
A4: 1.- Mejorar la eficiencia en la gestión de procesos asistenciales. | B4: 1.9 Personas que abandonan durante el Proceso de Atención de Urgencia en las Unidades de Emergencia Hospitalaria Adulto y Pediátrica. | C4: 1.9 | D4: 46082 | E4: =F4-[6]A08!$B$12 -> 814 | F4: =[6]A08!$AS$12 -> 3935 | G4: <10% | H4: =E4/F4 -> 0.2068615
A5: 1.- Mejorar la eficiencia en la gestión de procesos asistenciales. | B5: 1.9 Personas que abandonan durante el Proceso de Atención de Urgencia en las Unidades de Emergencia Hospitalaria Adulto y Pediátrica. | C5: 1.9 | D5: 46113 | E5: =F5-[7]A08!$B$12 -> 757 | F5: =[7]A08!$AS$12 -> 3707 | G5: <10% | H5: =E5/F5 -> 0.20420825
A6: 1.- Mejorar la eficiencia en la gestión de procesos asistenciales. | B6: 1.9 Personas que abandonan durante el Proceso de Atención de Urgencia en las Unidades de Emergencia Hospitalaria Adulto y Pediátrica. | C6: 1.9 | D6: 46143 | E6: =F6-[8]A08!$B$12 -> 742 | F6: =[8]A08!$AS$12 -> 3977 | G6: <10% | H6: =E6/F6 -> 0.18657279
A7: 1.- Mejorar la eficiencia en la gestión de procesos asistenciales. | B7: 1.9 Personas que abandonan durante el Proceso de Atención de Urgencia en las Unidades de Emergencia Hospitalaria Adulto y Pediátrica. | C7: 1.9 | D7: 46174 | E7: =F7-[9]A08!$B$12 -> 991 | F7: =[9]A08!$AS$12 -> 3903 | G7: <10% | H7: =E7/F7 -> 0.25390725
A8: 1.- Mejorar la eficiencia en la gestión de procesos asistenciales. | B8: 1.9 Personas que abandonan durante el Proceso de Atención de Urgencia en las Unidades de Emergencia Hospitalaria Adulto y Pediátrica. | C8: 1.9 | D8: 46204 | G8: <10% | H8: =E8/F8 -> #DIV/0!
A9: 1.- Mejorar la eficiencia en la gestión de procesos asistenciales. | B9: 1.9 Personas que abandonan durante el Proceso de Atención de Urgencia en las Unidades de Emergencia Hospitalaria Adulto y Pediátrica. | C9: 1.9 | D9: 46235 | G9: <10% | H9: =E9/F9 -> #DIV/0!
A10: 1.- Mejorar la eficiencia en la gestión de procesos asistenciales. | B10: 1.9 Personas que abandonan durante el Proceso de Atención de Urgencia en las Unidades de Emergencia Hospitalaria Adulto y Pediátrica. | C10: 1.9 | D10: 46266 | G10: <10% | H10: =E10/F10 -> #DIV/0!
A11: 1.- Mejorar la eficiencia en la gestión de procesos asistenciales. | B11: 1.9 Personas que abandonan durante el Proceso de Atención de Urgencia en las Unidades de Emergencia Hospitalaria Adulto y Pediátrica. | C11: 1.9 | D11: 46296 | G11: <10% | H11: =E11/F11 -> #DIV/0!
A12: 1.- Mejorar la eficiencia en la gestión de procesos asistenciales. | B12: 1.9 Personas que abandonan durante el Proceso de Atención de Urgencia en las Unidades de Emergencia Hospitalaria Adulto y Pediátrica. | C12: 1.9 | D12: 46327 | G12: <10% | H12: =E12/F12 -> #DIV/0!
A13: 1.- Mejorar la eficiencia en la gestión de procesos asistenciales. | B13: 1.9 Personas que abandonan durante el Proceso de Atención de Urgencia en las Unidades de Emergencia Hospitalaria Adulto y Pediátrica. | C13: 1.9 | D13: 46357 | G13: <10% | H13: =E13/F13 -> #DIV/0!
A14: 1.- Mejorar la eficiencia en la gestión de procesos asistenciales. | B14: 1.9 Personas que abandonan durante el Proceso de Atención de Urgencia en las Unidades de Emergencia Hospitalaria Adulto y Pediátrica. | C14: 1.9 | D14: TOTAL AÑO | E14: =SUM(E2:E13) -> 5584 | F14: =SUM(F2:F13) -> 24645 | G14: <10% | H14: =E14/F14 -> 0.2265774

Sheet 1,8 NSP CONTROL
A1: ESPECIALIDAD | B1: NUMERADOR ENERO | C1: DENOMINADOR ENERO | D1: RESULTADO ENERO | E1: NUMERADOR FEBRERO | F1: DENOMINADOR FEBRERO | G1: RESULTADO FEBRERO | H1: NUMERADOR MARZO | I1: DENOMINADOR MARZO | J1: RESULTADO MARZO | K1: NUMERADOR ABRIL | L1: DENOMINADOR ABRIL | M1: RESULTADO ABRIL | N1: NUMERADOR MAYO | O1: DENOMINADOR MAYO | P1: RESULTADO MAYO | Q1: NUMERADOR JUNIO | R1: DENOMINADOR JUNIO | S1: RESULTADO JUNIO | T1: NUMERADOR JULIO | U1: DENOMINADOR JULIO | V1: RESULTADO JULIO | W1: NUMERADOR AGOSTO | X1: DENOMINADOR AGOSTO | Y1: RESULTADO AGOSTO | Z1: NUMERADOR SEPT | AA1: DENOMINADOR SEPT | AB1: RESULTADO SEPT | AC1: NUMERADOR OCT | AD1: DENOMINADOR OCT | AE1: RESULTADO OCT | AF1: NUMERADOR NOV | AG1: DENOMINADOR NOV | AH1: RESULTADO NOV | AI1: NUMERADOR DIC | AJ1: DENOMINADOR DIC | AK1: RESULTADO DIC | AL1: NUMERADOR ANUAL | AM1: DENOMINADOR ANUAL | AN1: RESULTADO ANUAL | AO1: TOTAL AÑO | AP1: TOTAL ESPECIALIDADES | AQ1: CUMPLIMIENTO | AR1: META INDICADOR | AS1: % NSP
A2: Pediatría | B2: =[4]A07!$V$71+[4]A32!$W$35 -> 42 | C2: ='1,6 CN'!C2-'1,6 CN'!B2 -> 147 | D2: =IFERROR(B2/C2,"") -> 0.28571429 | E2: =[5]A07!$V$71+[5]A32!$W$35 -> 28 | F2: ='1,6 CN'!F2-'1,6 CN'!E2 -> 196 | G2: =IFERROR(E2/F2,"") -> 0.14285714 | H2: =[6]A07!$V$71+[6]A32!$W$35 -> 30 | I2: ='1,6 CN'!I2-'1,6 CN'!H2 -> 284 | J2: =IFERROR(H2/I2,"") -> 0.1056338 | K2: =[7]A07!$V$71+[7]A32!$W$35 -> 38 | L2: ='1,6 CN'!L2-'1,6 CN'!K2 -> 280 | M2: =IFERROR(K2/L2,"") -> 0.13571429 | N2: =[8]A07!$V$71+[8]A32!$W$35 -> 35 | O2: ='1,6 CN'!O2-'1,6 CN'!N2 -> 218 | P2: =N2/O2 -> 0.16055046 | S2: =Q2/R2 -> #DIV/0! | V2: =T2/U2 -> #DIV/0! | Y2: =W2/X2 -> #DIV/0! | AB2: =Z2/AA2 -> #DIV/0! | AE2: =AC2/AD2 -> #DIV/0! | AH2: =AF2/AG2 -> #DIV/0! | AK2: =+AI2/AJ2 -> #DIV/0! | AL2: =B2+E2+H2+K2+N2 -> 173 | AM2: =C2+F2+I2+L2+O2 -> 1125 | AN2: =IFERROR(AL2/AM2,"") -> 0.15377778 | AO2: =IF(AN2<10%,"1","0") -> 0 | AS2: <10%
A3: Medicina Interna | B3: =[4]A07!$V$72+[4]A32!$W$36 -> 40 | C3: ='1,6 CN'!C3-'1,6 CN'!B3 -> 464 | D3: =IFERROR(B3/C3,"") -> 0.086206897 | E3: =[5]A07!$V$72+[5]A32!$W$36 -> 34 | F3: ='1,6 CN'!F3-'1,6 CN'!E3 -> 374 | G3: =IFERROR(E3/F3,"") -> 0.090909091 | H3: =[6]A07!$V$72+[6]A32!$W$36 -> 22 | I3: ='1,6 CN'!I3-'1,6 CN'!H3 -> 289 | J3: =IFERROR(H3/I3,"") -> 0.076124567 | K3: =[7]A07!$V$72+[7]A32!$W$36 -> 45 | L3: ='1,6 CN'!L3-'1,6 CN'!K3 -> 465 | M3: =IFERROR(K3/L3,"") -> 0.096774194 | N3: =[8]A07!$V$72+[8]A32!$W$36 -> 34 | O3: ='1,6 CN'!O3-'1,6 CN'!N3 -> 356 | P3: =N3/O3 -> 0.095505618 | S3: =Q3/R3 -> #DIV/0! | V3: =T3/U3 -> #DIV/0! | Y3: =W3/X3 -> #DIV/0! | AB3: =Z3/AA3 -> #DIV/0! | AE3: =AC3/AD3 -> #DIV/0! | AH3: =AF3/AG3 -> #DIV/0! | AK3: =+AI3/AJ3 -> #DIV/0! | AL3: =B3+E3+H3+K3+N3 -> 175 | AM3: =C3+F3+I3+L3+O3 -> 1948 | AN3: =IFERROR(AL3/AM3,"") -> 0.089835729 | AO3: =IF(AN3<10%,"1","0") -> 1 | AS3: <10%
A4: Neonatología | B4: =[4]A07!$V$73+[4]A32!$W$37 -> 0 | C4: ='1,6 CN'!C4-'1,6 CN'!B4 -> 0 | D4: =IFERROR(B4/C4,"") | E4: =[5]A07!$V$73+[5]A32!$W$37 -> 0 | F4: ='1,6 CN'!F4-'1,6 CN'!E4 -> 0 | G4: =IFERROR(E4/F4,"") | H4: =[6]A07!$V$73+[6]A32!$W$37 -> 0 | I4: ='1,6 CN'!I4-'1,6 CN'!H4 -> 0 | J4: =IFERROR(H4/I4,"") | K4: =[7]A07!$V$73+[7]A32!$W$37 -> 0 | L4: ='1,6 CN'!L4-'1,6 CN'!K4 -> 0 | M4: =IFERROR(K4/L4,"") | N4: =[8]A07!$V$73+[8]A32!$W$37 -> 0 | O4: ='1,6 CN'!O4-'1,6 CN'!N4 -> 0 | P4: =N4/O4 -> #DIV/0! | S4: =Q4/R4 -> #DIV/0! | V4: =T4/U4 -> #DIV/0! | Y4: =W4/X4 -> #DIV/0! | AB4: =Z4/AA4 -> #DIV/0! | AE4: =AC4/AD4 -> #DIV/0! | AH4: =AF4/AG4 -> #DIV/0! | AK4: =+AI4/AJ4 -> #DIV/0! | AL4: =B4+E4+H4+K4+N4 -> 0 | AM4: =C4+F4+I4+L4+O4 -> 0 | AN4: =IFERROR(AL4/AM4,"") | AO4: =IF(AN4<10%,"1","0") -> 0 | AS4: <10%
A5: Enfermedad Respiratoria Pediátrica (Broncopulmonar Infantil) | B5: =[4]A07!$V$74+[4]A32!$W$38 -> 0 | C5: ='1,6 CN'!C5-'1,6 CN'!B5 -> 0 | D5: =IFERROR(B5/C5,"") | E5: =[5]A07!$V$74+[5]A32!$W$38 -> 0 | F5: ='1,6 CN'!F5-'1,6 CN'!E5 -> 0 | G5: =IFERROR(E5/F5,"") | H5: =[6]A07!$V$74+[6]A32!$W$38 -> 0 | I5: ='1,6 CN'!I5-'1,6 CN'!H5 -> 0 | J5: =IFERROR(H5/I5,"") | K5: =[7]A07!$V$74+[7]A32!$W$38 -> 0 | L5: ='1,6 CN'!L5-'1,6 CN'!K5 -> 0 | M5: =IFERROR(K5/L5,"") | N5: =[8]A07!$V$74+[8]A32!$W$38 -> 0 | O5: ='1,6 CN'!O5-'1,6 CN'!N5 -> 0 | P5: =N5/O5 -> #DIV/0! | S5: =Q5/R5 -> #DIV/0! | V5: =T5/U5 -> #DIV/0! | Y5: =W5/X5 -> #DIV/0! | AB5: =Z5/AA5 -> #DIV/0! | AE5: =AC5/AD5 -> #DIV/0! | AH5: =AF5/AG5 -> #DIV/0! | AK5: =+AI5/AJ5 -> #DIV/0! | AL5: =B5+E5+H5+K5+N5 -> 0 | AM5: =C5+F5+I5+L5+O5 -> 0 | AN5: =IFERROR(AL5/AM5,"") | AO5: =IF(AN5<10%,"1","0") -> 0 | AS5: <10%
A6: Enfermedad Respiratoria de Adulto (Broncopulmonar) | B6: =[4]A07!$V$75+[4]A32!$W$39 -> 0 | C6: ='1,6 CN'!C6-'1,6 CN'!B6 -> 0 | D6: =IFERROR(B6/C6,"") | E6: =[5]A07!$V$75+[5]A32!$W$39 -> 0 | F6: ='1,6 CN'!F6-'1,6 CN'!E6 -> 0 | G6: =IFERROR(E6/F6,"") | H6: =[6]A07!$V$75+[6]A32!$W$39 -> 0 | I6: ='1,6 CN'!I6-'1,6 CN'!H6 -> 0 | J6: =IFERROR(H6/I6,"") | K6: =[7]A07!$V$75+[7]A32!$W$39 -> 0 | L6: ='1,6 CN'!L6-'1,6 CN'!K6 -> 0 | M6: =IFERROR(K6/L6,"") | N6: =[8]A07!$V$75+[8]A32!$W$39 -> 0 | O6: ='1,6 CN'!O6-'1,6 CN'!N6 -> 0 | P6: =N6/O6 -> #DIV/0! | S6: =Q6/R6 -> #DIV/0! | V6: =T6/U6 -> #DIV/0! | Y6: =W6/X6 -> #DIV/0! | AB6: =Z6/AA6 -> #DIV/0! | AE6: =AC6/AD6 -> #DIV/0! | AH6: =AF6/AG6 -> #DIV/0! | AK6: =+AI6/AJ6 -> #DIV/0! | AL6: =B6+E6+H6+K6+N6 -> 0 | AM6: =C6+F6+I6+L6+O6 -> 0 | AN6: =IFERROR(AL6/AM6,"") | AO6: =IF(AN6<10%,"1","0") -> 0 | AS6: <10%
A7: Cardiología | B7: =[4]A07!$V$76+[4]A32!$W$40 -> 5 | C7: ='1,6 CN'!C7-'1,6 CN'!B7 -> 24 | D7: =IFERROR(B7/C7,"") -> 0.20833333 | E7: =[5]A07!$V$76+[5]A32!$W$40 -> 2 | F7: ='1,6 CN'!F7-'1,6 CN'!E7 -> 12 | G7: =IFERROR(E7/F7,"") -> 0.16666667 | H7: =[6]A07!$V$76+[6]A32!$W$40 -> 1 | I7: ='1,6 CN'!I7-'1,6 CN'!H7 -> 28 | J7: =IFERROR(H7/I7,"") -> 0.035714286 | K7: =[7]A07!$V$76+[7]A32!$W$40 -> 1 | L7: ='1,6 CN'!L7-'1,6 CN'!K7 -> 27 | M7: =IFERROR(K7/L7,"") -> 0.037037037 | N7: =[8]A07!$V$76+[8]A32!$W$40 -> 1 | O7: ='1,6 CN'!O7-'1,6 CN'!N7 -> 27 | P7: =N7/O7 -> 0.037037037 | S7: =Q7/R7 -> #DIV/0! | V7: =T7/U7 -> #DIV/0! | Y7: =W7/X7 -> #DIV/0! | AB7: =Z7/AA7 -> #DIV/0! | AE7: =AC7/AD7 -> #DIV/0! | AH7: =AF7/AG7 -> #DIV/0! | AK7: =+AI7/AJ7 -> #DIV/0! | AL7: =B7+E7+H7+K7+N7 -> 10 | AM7: =C7+F7+I7+L7+O7 -> 118 | AN7: =IFERROR(AL7/AM7,"") -> 0.084745763 | AO7: =IF(AN7<10%,"1","0") -> 1 | AS7: <10%
A8: Mastología | B8: =[4]A07!$V$77+[4]A32!$W$41 -> 11 | C8: ='1,6 CN'!C8-'1,6 CN'!B8 -> 182 | D8: =IFERROR(B8/C8,"") -> 0.06043956 | E8: =[5]A07!$V$77+[5]A32!$W$41 -> 1 | F8: ='1,6 CN'!F8-'1,6 CN'!E8 -> 148 | G8: =IFERROR(E8/F8,"") -> 0.0067567568 | H8: =[6]A07!$V$77+[6]A32!$W$41 -> 11 | I8: ='1,6 CN'!I8-'1,6 CN'!H8 -> 173 | J8: =IFERROR(H8/I8,"") -> 0.063583815 | K8: =[7]A07!$V$77+[7]A32!$W$41 -> 9 | L8: ='1,6 CN'!L8-'1,6 CN'!K8 -> 171 | M8: =IFERROR(K8/L8,"") -> 0.052631579 | N8: =[8]A07!$V$77+[8]A32!$W$41 -> 8 | O8: ='1,6 CN'!O8-'1,6 CN'!N8 -> 181 | P8: =N8/O8 -> 0.044198895 | S8: =Q8/R8 -> #DIV/0! | V8: =T8/U8 -> #DIV/0! | Y8: =W8/X8 -> #DIV/0! | AB8: =Z8/AA8 -> #DIV/0! | AE8: =AC8/AD8 -> #DIV/0! | AH8: =AF8/AG8 -> #DIV/0! | AK8: =+AI8/AJ8 -> #DIV/0! | AL8: =B8+E8+H8+K8+N8 -> 40 | AM8: =C8+F8+I8+L8+O8 -> 855 | AN8: =IFERROR(AL8/AM8,"") -> 0.046783626 | AO8: =IF(AN8<10%,"1","0") -> 1 | AS8: <10%
A9: Endocrinología Pediátrica | B9: =[4]A07!$V$78+[4]A32!$W$42 -> 2 | C9: ='1,6 CN'!C9-'1,6 CN'!B9 -> 71 | D9: =IFERROR(B9/C9,"") -> 0.028169014 | E9: =[5]A07!$V$78+[5]A32!$W$42 -> 2 | F9: ='1,6 CN'!F9-'1,6 CN'!E9 -> 77 | G9: =IFERROR(E9/F9,"") -> 0.025974026 | H9: =[6]A07!$V$78+[6]A32!$W$42 -> 0 | I9: ='1,6 CN'!I9-'1,6 CN'!H9 -> 68 | J9: =IFERROR(H9/I9,"") -> 0 | K9: =[7]A07!$V$78+[7]A32!$W$42 -> 3 | L9: ='1,6 CN'!L9-'1,6 CN'!K9 -> 66 | M9: =IFERROR(K9/L9,"") -> 0.045454545 | N9: =[8]A07!$V$78+[8]A32!$W$42 -> 2 | O9: ='1,6 CN'!O9-'1,6 CN'!N9 -> 61 | P9: =N9/O9 -> 0.032786885 | S9: =Q9/R9 -> #DIV/0! | V9: =T9/U9 -> #DIV/0! | Y9: =W9/X9 -> #DIV/0! | AB9: =Z9/AA9 -> #DIV/0! | AE9: =AC9/AD9 -> #DIV/0! | AH9: =AF9/AG9 -> #DIV/0! | AK9: =+AI9/AJ9 -> #DIV/0! | AL9: =B9+E9+H9+K9+N9 -> 9 | AM9: =C9+F9+I9+L9+O9 -> 343 | AN9: =IFERROR(AL9/AM9,"") -> 0.026239067 | AO9: =IF(AN9<10%,"1","0") -> 1 | AS9: <10%
A10: Endocrinología Adulto | B10: =[4]A07!$V$79+[4]A32!$W$43 -> 0 | C10: ='1,6 CN'!C10-'1,6 CN'!B10 -> 0 | D10: =IFERROR(B10/C10,"") | E10: =[5]A07!$V$79+[5]A32!$W$43 -> 0 | F10: ='1,6 CN'!F10-'1,6 CN'!E10 -> 0 | G10: =IFERROR(E10/F10,"") | H10: =[6]A07!$V$79+[6]A32!$W$43 -> 0 | I10: ='1,6 CN'!I10-'1,6 CN'!H10 -> 0 | J10: =IFERROR(H10/I10,"") | K10: =[7]A07!$V$79+[7]A32!$W$43 -> 0 | L10: ='1,6 CN'!L10-'1,6 CN'!K10 -> 0 | M10: =IFERROR(K10/L10,"") | N10: =[8]A07!$V$79+[8]A32!$W$43 -> 0 | O10: ='1,6 CN'!O10-'1,6 CN'!N10 -> 0 | P10: =N10/O10 -> #DIV/0! | S10: =Q10/R10 -> #DIV/0! | V10: =T10/U10 -> #DIV/0! | Y10: =W10/X10 -> #DIV/0! | AB10: =Z10/AA10 -> #DIV/0! | AE10: =AC10/AD10 -> #DIV/0! | AH10: =AF10/AG10 -> #DIV/0! | AK10: =+AI10/AJ10 -> #DIV/0! | AL10: =B10+E10+H10+K10+N10 -> 0 | AM10: =C10+F10+I10+L10+O10 -> 0 | AN10: =IFERROR(AL10/AM10,"") | AO10: =IF(AN10<10%,"1","0") -> 0 | AS10: <10%
A11: Gastroenterología Pediátrica | B11: =[4]A07!$V$80+[4]A32!$W$44 -> 0 | C11: ='1,6 CN'!C11-'1,6 CN'!B11 -> 0 | D11: =IFERROR(B11/C11,"") | E11: =[5]A07!$V$80+[5]A32!$W$44 -> 0 | F11: ='1,6 CN'!F11-'1,6 CN'!E11 -> 0 | G11: =IFERROR(E11/F11,"") | H11: =[6]A07!$V$80+[6]A32!$W$44 -> 0 | I11: ='1,6 CN'!I11-'1,6 CN'!H11 -> 0 | J11: =IFERROR(H11/I11,"") | K11: =[7]A07!$V$80+[7]A32!$W$44 -> 0 | L11: ='1,6 CN'!L11-'1,6 CN'!K11 -> 0 | M11: =IFERROR(K11/L11,"") | N11: =[8]A07!$V$80+[8]A32!$W$44 -> 0 | O11: ='1,6 CN'!O11-'1,6 CN'!N11 -> 0 | P11: =N11/O11 -> #DIV/0! | S11: =Q11/R11 -> #DIV/0! | V11: =T11/U11 -> #DIV/0! | Y11: =W11/X11 -> #DIV/0! | AB11: =Z11/AA11 -> #DIV/0! | AE11: =AC11/AD11 -> #DIV/0! | AH11: =AF11/AG11 -> #DIV/0! | AK11: =+AI11/AJ11 -> #DIV/0! | AL11: =B11+E11+H11+K11+N11 -> 0 | AM11: =C11+F11+I11+L11+O11 -> 0 | AN11: =IFERROR(AL11/AM11,"") | AO11: =IF(AN11<10%,"1","0") -> 0 | AS11: <10%
A12: Gastroenterología Adulto | B12: =[4]A07!$V$81+[4]A32!$W$45 -> 1 | C12: ='1,6 CN'!C12-'1,6 CN'!B12 -> 5 | D12: =IFERROR(B12/C12,"") -> 0.2 | E12: =[5]A07!$V$81+[5]A32!$W$45 -> 0 | F12: ='1,6 CN'!F12-'1,6 CN'!E12 -> 0 | G12: =IFERROR(E12/F12,"") | H12: =[6]A07!$V$81+[6]A32!$W$45 -> 4 | I12: ='1,6 CN'!I12-'1,6 CN'!H12 -> 22 | J12: =IFERROR(H12/I12,"") -> 0.18181818 | K12: =[7]A07!$V$81+[7]A32!$W$45 -> 1 | L12: ='1,6 CN'!L12-'1,6 CN'!K12 -> 16 | M12: =IFERROR(K12/L12,"") -> 0.0625 | N12: =[8]A07!$V$81+[8]A32!$W$45 -> 1 | O12: ='1,6 CN'!O12-'1,6 CN'!N12 -> 9 | P12: =N12/O12 -> 0.11111111 | S12: =Q12/R12 -> #DIV/0! | V12: =T12/U12 -> #DIV/0! | Y12: =W12/X12 -> #DIV/0! | AB12: =Z12/AA12 -> #DIV/0! | AE12: =AC12/AD12 -> #DIV/0! | AH12: =AF12/AG12 -> #DIV/0! | AK12: =+AI12/AJ12 -> #DIV/0! | AL12: =B12+E12+H12+K12+N12 -> 7 | AM12: =C12+F12+I12+L12+O12 -> 52 | AN12: =IFERROR(AL12/AM12,"") -> 0.13461538 | AO12: =IF(AN12<10%,"1","0") -> 0 | AS12: <10%
A13: Genética Clínica | B13: =[4]A07!$V$82+[4]A32!$W$46 -> 0 | C13: ='1,6 CN'!C13-'1,6 CN'!B13 -> 0 | D13: =IFERROR(B13/C13,"") | E13: =[5]A07!$V$82+[5]A32!$W$46 -> 0 | F13: ='1,6 CN'!F13-'1,6 CN'!E13 -> 0 | G13: =IFERROR(E13/F13,"") | H13: =[6]A07!$V$82+[6]A32!$W$46 -> 0 | I13: ='1,6 CN'!I13-'1,6 CN'!H13 -> 0 | J13: =IFERROR(H13/I13,"") | K13: =[7]A07!$V$82+[7]A32!$W$46 -> 0 | L13: ='1,6 CN'!L13-'1,6 CN'!K13 -> 0 | M13: =IFERROR(K13/L13,"") | N13: =[8]A07!$V$82+[8]A32!$W$46 -> 0 | O13: ='1,6 CN'!O13-'1,6 CN'!N13 -> 0 | P13: =N13/O13 -> #DIV/0! | S13: =Q13/R13 -> #DIV/0! | V13: =T13/U13 -> #DIV/0! | Y13: =W13/X13 -> #DIV/0! | AB13: =Z13/AA13 -> #DIV/0! | AE13: =AC13/AD13 -> #DIV/0! | AH13: =AF13/AG13 -> #DIV/0! | AK13: =+AI13/AJ13 -> #DIV/0! | AL13: =B13+E13+H13+K13+N13 -> 0 | AM13: =C13+F13+I13+L13+O13 -> 0 | AN13: =IFERROR(AL13/AM13,"") | AO13: =IF(AN13<10%,"1","0") -> 0 | AS13: <10%
A14: Hematología | B14: =[4]A07!$V$83+[4]A32!$W$47 -> 0 | C14: ='1,6 CN'!C14-'1,6 CN'!B14 -> 0 | D14: =IFERROR(B14/C14,"") | E14: =[5]A07!$V$83+[5]A32!$W$47 -> 0 | F14: ='1,6 CN'!F14-'1,6 CN'!E14 -> 0 | G14: =IFERROR(E14/F14,"") | H14: =[6]A07!$V$83+[6]A32!$W$47 -> 0 | I14: ='1,6 CN'!I14-'1,6 CN'!H14 -> 0 | J14: =IFERROR(H14/I14,"") | K14: =[7]A07!$V$83+[7]A32!$W$47 -> 0 | L14: ='1,6 CN'!L14-'1,6 CN'!K14 -> 0 | M14: =IFERROR(K14/L14,"") | N14: =[8]A07!$V$83+[8]A32!$W$47 -> 0 | O14: ='1,6 CN'!O14-'1,6 CN'!N14 -> 0 | P14: =N14/O14 -> #DIV/0! | S14: =Q14/R14 -> #DIV/0! | V14: =T14/U14 -> #DIV/0! | Y14: =W14/X14 -> #DIV/0! | AB14: =Z14/AA14 -> #DIV/0! | AE14: =AC14/AD14 -> #DIV/0! | AH14: =AF14/AG14 -> #DIV/0! | AK14: =+AI14/AJ14 -> #DIV/0! | AL14: =B14+E14+H14+K14+N14 -> 0 | AM14: =C14+F14+I14+L14+O14 -> 0 | AN14: =IFERROR(AL14/AM14,"") | AO14: =IF(AN14<10%,"1","0") -> 0 | AS14: <10%
A15: Medicina del adolescente | B15: =[4]A07!$V$84+[4]A32!$W$48 -> 0 | C15: ='1,6 CN'!C15-'1,6 CN'!B15 -> 0 | D15: =IFERROR(B15/C15,"") | E15: =[5]A07!$V$84+[5]A32!$W$48 -> 0 | F15: ='1,6 CN'!F15-'1,6 CN'!E15 -> 0 | G15: =IFERROR(E15/F15,"") | H15: =[6]A07!$V$84+[6]A32!$W$48 -> 0 | I15: ='1,6 CN'!I15-'1,6 CN'!H15 -> 0 | J15: =IFERROR(H15/I15,"") | K15: =[7]A07!$V$84+[7]A32!$W$48 -> 0 | L15: ='1,6 CN'!L15-'1,6 CN'!K15 -> 0 | M15: =IFERROR(K15/L15,"") | N15: =[8]A07!$V$84+[8]A32!$W$48 -> 0 | O15: ='1,6 CN'!O15-'1,6 CN'!N15 -> 0 | P15: =N15/O15 -> #DIV/0! | S15: =Q15/R15 -> #DIV/0! | V15: =T15/U15 -> #DIV/0! | Y15: =W15/X15 -> #DIV/0! | AB15: =Z15/AA15 -> #DIV/0! | AE15: =AC15/AD15 -> #DIV/0! | AH15: =AF15/AG15 -> #DIV/0! | AK15: =+AI15/AJ15 -> #DIV/0! | AL15: =B15+E15+H15+K15+N15 -> 0 | AM15: =C15+F15+I15+L15+O15 -> 0 | AN15: =IFERROR(AL15/AM15,"") | AO15: =IF(AN15<10%,"1","0") -> 0 | AS15: <10%
A16: Nefrología Pediátrica | B16: =[4]A07!$V$85+[4]A32!$W$49 -> 0 | C16: ='1,6 CN'!C16-'1,6 CN'!B16 -> 0 | D16: =IFERROR(B16/C16,"") | E16: =[5]A07!$V$85+[5]A32!$W$49 -> 0 | F16: ='1,6 CN'!F16-'1,6 CN'!E16 -> 0 | G16: =IFERROR(E16/F16,"") | H16: =[6]A07!$V$85+[6]A32!$W$49 -> 0 | I16: ='1,6 CN'!I16-'1,6 CN'!H16 -> 0 | J16: =IFERROR(H16/I16,"") | K16: =[7]A07!$V$85+[7]A32!$W$49 -> 0 | L16: ='1,6 CN'!L16-'1,6 CN'!K16 -> 0 | M16: =IFERROR(K16/L16,"") | N16: =[8]A07!$V$85+[8]A32!$W$49 -> 0 | O16: ='1,6 CN'!O16-'1,6 CN'!N16 -> 0 | P16: =N16/O16 -> #DIV/0! | S16: =Q16/R16 -> #DIV/0! | V16: =T16/U16 -> #DIV/0! | Y16: =W16/X16 -> #DIV/0! | AB16: =Z16/AA16 -> #DIV/0! | AE16: =AC16/AD16 -> #DIV/0! | AH16: =AF16/AG16 -> #DIV/0! | AK16: =+AI16/AJ16 -> #DIV/0! | AL16: =B16+E16+H16+K16+N16 -> 0 | AM16: =C16+F16+I16+L16+O16 -> 0 | AN16: =IFERROR(AL16/AM16,"") | AO16: =IF(AN16<10%,"1","0") -> 0 | AS16: <10%
A17: Nefrología Adulto | B17: =[4]A07!$V$86+[4]A32!$W$50 -> 0 | C17: ='1,6 CN'!C17-'1,6 CN'!B17 -> 4 | D17: =IFERROR(B17/C17,"") -> 0 | E17: =[5]A07!$V$86+[5]A32!$W$50 -> 0 | F17: ='1,6 CN'!F17-'1,6 CN'!E17 -> 0 | G17: =IFERROR(E17/F17,"") | H17: =[6]A07!$V$86+[6]A32!$W$50 -> 0 | I17: ='1,6 CN'!I17-'1,6 CN'!H17 -> 13 | J17: =IFERROR(H17/I17,"") -> 0 | K17: =[7]A07!$V$86+[7]A32!$W$50 -> 0 | L17: ='1,6 CN'!L17-'1,6 CN'!K17 -> 21 | M17: =IFERROR(K17/L17,"") -> 0 | N17: =[8]A07!$V$86+[8]A32!$W$50 -> 0 | O17: ='1,6 CN'!O17-'1,6 CN'!N17 -> 0 | P17: =N17/O17 -> #DIV/0! | S17: =Q17/R17 -> #DIV/0! | V17: =T17/U17 -> #DIV/0! | Y17: =W17/X17 -> #DIV/0! | AB17: =Z17/AA17 -> #DIV/0! | AE17: =AC17/AD17 -> #DIV/0! | AH17: =AF17/AG17 -> #DIV/0! | AK17: =+AI17/AJ17 -> #DIV/0! | AL17: =B17+E17+H17+K17+N17 -> 0 | AM17: =C17+F17+I17+L17+O17 -> 38 | AN17: =IFERROR(AL17/AM17,"") -> 0 | AO17: =IF(AN17<10%,"1","0") -> 1 | AS17: <10%
A18: Nutrición clínica | B18: =[4]A07!$V$87+[4]A32!$W$51 -> 0 | C18: ='1,6 CN'!C18-'1,6 CN'!B18 -> 0 | D18: =IFERROR(B18/C18,"") | E18: =[5]A07!$V$87+[5]A32!$W$51 -> 0 | F18: ='1,6 CN'!F18-'1,6 CN'!E18 -> 0 | G18: =IFERROR(E18/F18,"") | H18: =[6]A07!$V$87+[6]A32!$W$51 -> 0 | I18: ='1,6 CN'!I18-'1,6 CN'!H18 -> 0 | J18: =IFERROR(H18/I18,"") | K18: =[7]A07!$V$87+[7]A32!$W$51 -> 0 | L18: ='1,6 CN'!L18-'1,6 CN'!K18 -> 0 | M18: =IFERROR(K18/L18,"") | N18: =[8]A07!$V$87+[8]A32!$W$51 -> 0 | O18: ='1,6 CN'!O18-'1,6 CN'!N18 -> 0 | P18: =N18/O18 -> #DIV/0! | S18: =Q18/R18 -> #DIV/0! | V18: =T18/U18 -> #DIV/0! | Y18: =W18/X18 -> #DIV/0! | AB18: =Z18/AA18 -> #DIV/0! | AE18: =AC18/AD18 -> #DIV/0! | AH18: =AF18/AG18 -> #DIV/0! | AK18: =+AI18/AJ18 -> #DIV/0! | AL18: =B18+E18+H18+K18+N18 -> 0 | AM18: =C18+F18+I18+L18+O18 -> 0 | AN18: =IFERROR(AL18/AM18,"") | AO18: =IF(AN18<10%,"1","0") -> 0 | AS18: <10%
A19: Medicina Materno Infantil | B19: =[4]A07!$V$88+[4]A32!$W$52 -> 0 | C19: ='1,6 CN'!C19-'1,6 CN'!B19 -> 0 | D19: =IFERROR(B19/C19,"") | E19: =[5]A07!$V$88+[5]A32!$W$52 -> 0 | F19: ='1,6 CN'!F19-'1,6 CN'!E19 -> 0 | G19: =IFERROR(E19/F19,"") | H19: =[6]A07!$V$88+[6]A32!$W$52 -> 0 | I19: ='1,6 CN'!I19-'1,6 CN'!H19 -> 0 | J19: =IFERROR(H19/I19,"") | K19: =[7]A07!$V$88+[7]A32!$W$52 -> 0 | L19: ='1,6 CN'!L19-'1,6 CN'!K19 -> 0 | M19: =IFERROR(K19/L19,"") | N19: =[8]A07!$V$88+[8]A32!$W$52 -> 0 | O19: ='1,6 CN'!O19-'1,6 CN'!N19 -> 0 | P19: =N19/O19 -> #DIV/0! | S19: =Q19/R19 -> #DIV/0! | V19: =T19/U19 -> #DIV/0! | Y19: =W19/X19 -> #DIV/0! | AB19: =Z19/AA19 -> #DIV/0! | AE19: =AC19/AD19 -> #DIV/0! | AH19: =AF19/AG19 -> #DIV/0! | AK19: =+AI19/AJ19 -> #DIV/0! | AL19: =B19+E19+H19+K19+N19 -> 0 | AM19: =C19+F19+I19+L19+O19 -> 0 | AN19: =IFERROR(AL19/AM19,"") | AO19: =IF(AN19<10%,"1","0") -> 0 | AS19: <10%
A20: Reumatología | B20: =[4]A07!$V$89+[4]A32!$W$53 -> 0 | C20: ='1,6 CN'!C20-'1,6 CN'!B20 -> 0 | D20: =IFERROR(B20/C20,"") | E20: =[5]A07!$V$89+[5]A32!$W$53 -> 0 | F20: ='1,6 CN'!F20-'1,6 CN'!E20 -> 0 | G20: =IFERROR(E20/F20,"") | H20: =[6]A07!$V$89+[6]A32!$W$53 -> 0 | I20: ='1,6 CN'!I20-'1,6 CN'!H20 -> 0 | J20: =IFERROR(H20/I20,"") | K20: =[7]A07!$V$89+[7]A32!$W$53 -> 0 | L20: ='1,6 CN'!L20-'1,6 CN'!K20 -> 0 | M20: =IFERROR(K20/L20,"") | N20: =[8]A07!$V$89+[8]A32!$W$53 -> 0 | O20: ='1,6 CN'!O20-'1,6 CN'!N20 -> 0 | P20: =N20/O20 -> #DIV/0! | S20: =Q20/R20 -> #DIV/0! | V20: =T20/U20 -> #DIV/0! | Y20: =W20/X20 -> #DIV/0! | AB20: =Z20/AA20 -> #DIV/0! | AE20: =AC20/AD20 -> #DIV/0! | AH20: =AF20/AG20 -> #DIV/0! | AK20: =+AI20/AJ20 -> #DIV/0! | AL20: =B20+E20+H20+K20+N20 -> 0 | AM20: =C20+F20+I20+L20+O20 -> 0 | AN20: =IFERROR(AL20/AM20,"") | AO20: =IF(AN20<10%,"1","0") -> 0 | AS20: <10%
A21: Medicina Paliativa y de Manejo del Dolor | B21: =[4]A07!$V$90+[4]A32!$W$54 -> 0 | C21: ='1,6 CN'!C21-'1,6 CN'!B21 -> 0 | D21: =IFERROR(B21/C21,"") | E21: =[5]A07!$V$90+[5]A32!$W$54 -> 0 | F21: ='1,6 CN'!F21-'1,6 CN'!E21 -> 0 | G21: =IFERROR(E21/F21,"") | H21: =[6]A07!$V$90+[6]A32!$W$54 -> 0 | I21: ='1,6 CN'!I21-'1,6 CN'!H21 -> 0 | J21: =IFERROR(H21/I21,"") | K21: =[7]A07!$V$90+[7]A32!$W$54 -> 0 | L21: ='1,6 CN'!L21-'1,6 CN'!K21 -> 0 | M21: =IFERROR(K21/L21,"") | N21: =[8]A07!$V$90+[8]A32!$W$54 -> 0 | O21: ='1,6 CN'!O21-'1,6 CN'!N21 -> 0 | P21: =N21/O21 -> #DIV/0! | S21: =Q21/R21 -> #DIV/0! | V21: =T21/U21 -> #DIV/0! | Y21: =W21/X21 -> #DIV/0! | AB21: =Z21/AA21 -> #DIV/0! | AE21: =AC21/AD21 -> #DIV/0! | AH21: =AF21/AG21 -> #DIV/0! | AK21: =+AI21/AJ21 -> #DIV/0! | AL21: =B21+E21+H21+K21+N21 -> 0 | AM21: =C21+F21+I21+L21+O21 -> 0 | AN21: =IFERROR(AL21/AM21,"") | AO21: =IF(AN21<10%,"1","0") -> 0 | AS21: <10%
A22: Dermatología | B22: =[4]A07!$V$91+[4]A32!$W$55 -> 3 | C22: ='1,6 CN'!C22-'1,6 CN'!B22 -> 43 | D22: =IFERROR(B22/C22,"") -> 0.069767442 | E22: =[5]A07!$V$91+[5]A32!$W$55 -> 6 | F22: ='1,6 CN'!F22-'1,6 CN'!E22 -> 35 | G22: =IFERROR(E22/F22,"") -> 0.17142857 | H22: =[6]A07!$V$91+[6]A32!$W$55 -> 15 | I22: ='1,6 CN'!I22-'1,6 CN'!H22 -> 65 | J22: =IFERROR(H22/I22,"") -> 0.23076923 | K22: =[7]A07!$V$91+[7]A32!$W$55 -> 11 | L22: ='1,6 CN'!L22-'1,6 CN'!K22 -> 63 | M22: =IFERROR(K22/L22,"") -> 0.17460317 | N22: =[8]A07!$V$91+[8]A32!$W$55 -> 19 | O22: ='1,6 CN'!O22-'1,6 CN'!N22 -> 67 | P22: =N22/O22 -> 0.28358209 | S22: =Q22/R22 -> #DIV/0! | V22: =T22/U22 -> #DIV/0! | Y22: =W22/X22 -> #DIV/0! | AB22: =Z22/AA22 -> #DIV/0! | AE22: =AC22/AD22 -> #DIV/0! | AH22: =AF22/AG22 -> #DIV/0! | AK22: =+AI22/AJ22 -> #DIV/0! | AL22: =B22+E22+H22+K22+N22 -> 54 | AM22: =C22+F22+I22+L22+O22 -> 273 | AN22: =IFERROR(AL22/AM22,"") -> 0.1978022 | AO22: =IF(AN22<10%,"1","0") -> 0 | AS22: <10%
A23: Infectología | B23: =[4]A07!$V$92+[4]A32!$W$56 -> 0 | C23: ='1,6 CN'!C23-'1,6 CN'!B23 -> 0 | D23: =IFERROR(B23/C23,"") | E23: =[5]A07!$V$92+[5]A32!$W$56 -> 0 | F23: ='1,6 CN'!F23-'1,6 CN'!E23 -> 0 | G23: =IFERROR(E23/F23,"") | H23: =[6]A07!$V$92+[6]A32!$W$56 -> 0 | I23: ='1,6 CN'!I23-'1,6 CN'!H23 -> 0 | J23: =IFERROR(H23/I23,"") | K23: =[7]A07!$V$92+[7]A32!$W$56 -> 0 | L23: ='1,6 CN'!L23-'1,6 CN'!K23 -> 0 | M23: =IFERROR(K23/L23,"") | N23: =[8]A07!$V$92+[8]A32!$W$56 -> 0 | O23: ='1,6 CN'!O23-'1,6 CN'!N23 -> 0 | P23: =N23/O23 -> #DIV/0! | S23: =Q23/R23 -> #DIV/0! | V23: =T23/U23 -> #DIV/0! | Y23: =W23/X23 -> #DIV/0! | AB23: =Z23/AA23 -> #DIV/0! | AE23: =AC23/AD23 -> #DIV/0! | AH23: =AF23/AG23 -> #DIV/0! | AK23: =+AI23/AJ23 -> #DIV/0! | AL23: =B23+E23+H23+K23+N23 -> 0 | AM23: =C23+F23+I23+L23+O23 -> 0 | AN23: =IFERROR(AL23/AM23,"") | AO23: =IF(AN23<10%,"1","0") -> 0 | AS23: <10%
